[2025-05-12T21:52:30.096+0500] {taskinstance.py:1159} INFO - Dependencies all met for dep_context=non-requeueable deps ti=<TaskInstance: data_pipeline_dag.track_raw_data manual__2025-05-12T16:52:11.759902+00:00 [queued]>
[2025-05-12T21:52:30.102+0500] {taskinstance.py:1159} INFO - Dependencies all met for dep_context=requeueable deps ti=<TaskInstance: data_pipeline_dag.track_raw_data manual__2025-05-12T16:52:11.759902+00:00 [queued]>
[2025-05-12T21:52:30.102+0500] {taskinstance.py:1361} INFO - Starting attempt 1 of 1
[2025-05-12T21:52:30.217+0500] {taskinstance.py:1382} INFO - Executing <Task(PythonOperator): track_raw_data> on 2025-05-12 16:52:11.759902+00:00
[2025-05-12T21:52:30.228+0500] {standard_task_runner.py:57} INFO - Started process 63736 to run task
[2025-05-12T21:52:30.233+0500] {standard_task_runner.py:84} INFO - Running: ['airflow', 'tasks', 'run', 'data_pipeline_dag', 'track_raw_data', 'manual__2025-05-12T16:52:11.759902+00:00', '--job-id', '28', '--raw', '--subdir', 'DAGS_FOLDER/mlflow.py', '--cfg-path', '/tmp/tmp5tl04htk']
[2025-05-12T21:52:30.233+0500] {standard_task_runner.py:85} INFO - Job 28: Subtask track_raw_data
[2025-05-12T21:52:30.392+0500] {task_command.py:416} INFO - Running <TaskInstance: data_pipeline_dag.track_raw_data manual__2025-05-12T16:52:11.759902+00:00 [running]> on host maemoon-Inspiron-15-3567
[2025-05-12T21:52:30.640+0500] {taskinstance.py:1662} INFO - Exporting env vars: AIRFLOW_CTX_DAG_OWNER='airflow' AIRFLOW_CTX_DAG_ID='data_pipeline_dag' AIRFLOW_CTX_TASK_ID='track_raw_data' AIRFLOW_CTX_EXECUTION_DATE='2025-05-12T16:52:11.759902+00:00' AIRFLOW_CTX_TRY_NUMBER='1' AIRFLOW_CTX_DAG_RUN_ID='manual__2025-05-12T16:52:11.759902+00:00'
[2025-05-12T21:52:32.732+0500] {logging_mixin.py:151} INFO - Raw data tracked with DVC
[2025-05-12T21:52:32.901+0500] {taskinstance.py:1937} ERROR - Task failed with exception
Traceback (most recent call last):
  File "/home/maemoon/Documents/MLOPS_Project/env/lib/python3.10/site-packages/airflow/operators/python.py", line 192, in execute
    return_value = self.execute_callable()
  File "/home/maemoon/Documents/MLOPS_Project/env/lib/python3.10/site-packages/airflow/operators/python.py", line 209, in execute_callable
    return self.python_callable(*self.op_args, **self.op_kwargs)
  File "/home/maemoon/Documents/MLOPS_Project/dags/Tasks/tracking.py", line 12, in track_raw_data
    mlflow.log_artifact('WeatherData/Lahore_Forecast.csv')
  File "/home/maemoon/Documents/MLOPS_Project/env/lib/python3.10/site-packages/mlflow/tracking/fluent.py", line 1179, in log_artifact
    MlflowClient().log_artifact(run_id, local_path, artifact_path)
  File "/home/maemoon/Documents/MLOPS_Project/env/lib/python3.10/site-packages/mlflow/tracking/client.py", line 2379, in log_artifact
    self._tracking_client.log_artifact(run_id, local_path, artifact_path)
  File "/home/maemoon/Documents/MLOPS_Project/env/lib/python3.10/site-packages/mlflow/tracking/_tracking_service/client.py", line 923, in log_artifact
    artifact_repo = self._get_artifact_repo(run_id)
  File "/home/maemoon/Documents/MLOPS_Project/env/lib/python3.10/site-packages/mlflow/tracking/_tracking_service/client.py", line 906, in _get_artifact_repo
    artifact_repo = get_artifact_repository(artifact_uri)
  File "/home/maemoon/Documents/MLOPS_Project/env/lib/python3.10/site-packages/mlflow/store/artifact/artifact_repository_registry.py", line 133, in get_artifact_repository
    return _artifact_repository_registry.get_artifact_repository(artifact_uri)
  File "/home/maemoon/Documents/MLOPS_Project/env/lib/python3.10/site-packages/mlflow/store/artifact/artifact_repository_registry.py", line 77, in get_artifact_repository
    return repository(artifact_uri)
  File "/home/maemoon/Documents/MLOPS_Project/env/lib/python3.10/site-packages/mlflow/store/artifact/mlflow_artifacts_repo.py", line 51, in __init__
    super().__init__(self.resolve_uri(artifact_uri, get_tracking_uri()))
  File "/home/maemoon/Documents/MLOPS_Project/env/lib/python3.10/site-packages/mlflow/store/artifact/mlflow_artifacts_repo.py", line 65, in resolve_uri
    _validate_uri_scheme(track_parse)
  File "/home/maemoon/Documents/MLOPS_Project/env/lib/python3.10/site-packages/mlflow/store/artifact/mlflow_artifacts_repo.py", line 35, in _validate_uri_scheme
    raise MlflowException(
mlflow.exceptions.MlflowException: When an mlflow-artifacts URI was supplied, the tracking URI must be a valid http or https URI, but it was currently set to file:///home/maemoon/Documents/MLOPS_Project/mlruns. Perhaps you forgot to set the tracking URI to the running MLflow server. To set the tracking URI, use either of the following methods:
1. Set the MLFLOW_TRACKING_URI environment variable to the desired tracking URI. `export MLFLOW_TRACKING_URI=http://localhost:5000`
2. Set the tracking URI programmatically by calling `mlflow.set_tracking_uri`. `mlflow.set_tracking_uri('http://localhost:5000')`
[2025-05-12T21:52:32.976+0500] {taskinstance.py:1400} INFO - Marking task as FAILED. dag_id=data_pipeline_dag, task_id=track_raw_data, execution_date=20250512T165211, start_date=20250512T165230, end_date=20250512T165232
[2025-05-12T21:52:33.128+0500] {standard_task_runner.py:104} ERROR - Failed to execute job 28 for task track_raw_data (When an mlflow-artifacts URI was supplied, the tracking URI must be a valid http or https URI, but it was currently set to file:///home/maemoon/Documents/MLOPS_Project/mlruns. Perhaps you forgot to set the tracking URI to the running MLflow server. To set the tracking URI, use either of the following methods:
1. Set the MLFLOW_TRACKING_URI environment variable to the desired tracking URI. `export MLFLOW_TRACKING_URI=http://localhost:5000`
2. Set the tracking URI programmatically by calling `mlflow.set_tracking_uri`. `mlflow.set_tracking_uri('http://localhost:5000')`; 63736)
[2025-05-12T21:52:33.137+0500] {local_task_job_runner.py:228} INFO - Task exited with return code 1
[2025-05-12T21:52:33.152+0500] {taskinstance.py:2778} INFO - 0 downstream tasks scheduled from follow-on schedule check
