[2025-05-12T21:23:46.223+0500] {taskinstance.py:1159} INFO - Dependencies all met for dep_context=non-requeueable deps ti=<TaskInstance: data_pipeline_dag.track_raw_data scheduled__2023-01-01T00:00:00+00:00 [queued]>
[2025-05-12T21:23:46.230+0500] {taskinstance.py:1159} INFO - Dependencies all met for dep_context=requeueable deps ti=<TaskInstance: data_pipeline_dag.track_raw_data scheduled__2023-01-01T00:00:00+00:00 [queued]>
[2025-05-12T21:23:46.230+0500] {taskinstance.py:1361} INFO - Starting attempt 1 of 1
[2025-05-12T21:23:46.385+0500] {taskinstance.py:1382} INFO - Executing <Task(PythonOperator): track_raw_data> on 2023-01-01 00:00:00+00:00
[2025-05-12T21:23:46.389+0500] {standard_task_runner.py:57} INFO - Started process 55925 to run task
[2025-05-12T21:23:46.392+0500] {standard_task_runner.py:84} INFO - Running: ['airflow', 'tasks', 'run', 'data_pipeline_dag', 'track_raw_data', 'scheduled__2023-01-01T00:00:00+00:00', '--job-id', '5', '--raw', '--subdir', 'DAGS_FOLDER/mlflow.py', '--cfg-path', '/tmp/tmprlih7oz7']
[2025-05-12T21:23:46.392+0500] {standard_task_runner.py:85} INFO - Job 5: Subtask track_raw_data
[2025-05-12T21:23:46.544+0500] {task_command.py:416} INFO - Running <TaskInstance: data_pipeline_dag.track_raw_data scheduled__2023-01-01T00:00:00+00:00 [running]> on host maemoon-Inspiron-15-3567
[2025-05-12T21:23:46.746+0500] {taskinstance.py:1662} INFO - Exporting env vars: AIRFLOW_CTX_DAG_OWNER='airflow' AIRFLOW_CTX_DAG_ID='data_pipeline_dag' AIRFLOW_CTX_TASK_ID='track_raw_data' AIRFLOW_CTX_EXECUTION_DATE='2023-01-01T00:00:00+00:00' AIRFLOW_CTX_TRY_NUMBER='1' AIRFLOW_CTX_DAG_RUN_ID='scheduled__2023-01-01T00:00:00+00:00'
[2025-05-12T21:23:46.749+0500] {taskinstance.py:1937} ERROR - Task failed with exception
Traceback (most recent call last):
  File "/home/maemoon/Documents/MLOPS_Project/env/lib/python3.10/site-packages/airflow/operators/python.py", line 192, in execute
    return_value = self.execute_callable()
  File "/home/maemoon/Documents/MLOPS_Project/env/lib/python3.10/site-packages/airflow/operators/python.py", line 209, in execute_callable
    return self.python_callable(*self.op_args, **self.op_kwargs)
  File "/home/maemoon/Documents/MLOPS_Project/dags/Tasks/tracking.py", line 6, in track_raw_data
    subprocess.run(['dvc', 'add', 'WeatherData/Lahore_Forecast.csv'])
  File "/usr/lib/python3.10/subprocess.py", line 503, in run
    with Popen(*popenargs, **kwargs) as process:
  File "/usr/lib/python3.10/subprocess.py", line 971, in __init__
    self._execute_child(args, executable, preexec_fn, close_fds,
  File "/usr/lib/python3.10/subprocess.py", line 1863, in _execute_child
    raise child_exception_type(errno_num, err_msg, err_filename)
FileNotFoundError: [Errno 2] No such file or directory: 'dvc'
[2025-05-12T21:23:46.790+0500] {taskinstance.py:1400} INFO - Marking task as FAILED. dag_id=data_pipeline_dag, task_id=track_raw_data, execution_date=20230101T000000, start_date=20250512T162346, end_date=20250512T162346
[2025-05-12T21:23:46.909+0500] {standard_task_runner.py:104} ERROR - Failed to execute job 5 for task track_raw_data ([Errno 2] No such file or directory: 'dvc'; 55925)
[2025-05-12T21:23:46.925+0500] {local_task_job_runner.py:228} INFO - Task exited with return code 1
[2025-05-12T21:23:46.944+0500] {taskinstance.py:2778} INFO - 0 downstream tasks scheduled from follow-on schedule check
