[2025-05-12T21:23:55.060+0500] {taskinstance.py:1159} INFO - Dependencies all met for dep_context=non-requeueable deps ti=<TaskInstance: data_pipeline_dag.track_raw_data manual__2025-05-12T16:23:27.408692+00:00 [queued]>
[2025-05-12T21:23:55.068+0500] {taskinstance.py:1159} INFO - Dependencies all met for dep_context=requeueable deps ti=<TaskInstance: data_pipeline_dag.track_raw_data manual__2025-05-12T16:23:27.408692+00:00 [queued]>
[2025-05-12T21:23:55.068+0500] {taskinstance.py:1361} INFO - Starting attempt 1 of 1
[2025-05-12T21:23:55.231+0500] {taskinstance.py:1382} INFO - Executing <Task(PythonOperator): track_raw_data> on 2025-05-12 16:23:27.408692+00:00
[2025-05-12T21:23:55.235+0500] {standard_task_runner.py:57} INFO - Started process 56044 to run task
[2025-05-12T21:23:55.238+0500] {standard_task_runner.py:84} INFO - Running: ['airflow', 'tasks', 'run', 'data_pipeline_dag', 'track_raw_data', 'manual__2025-05-12T16:23:27.408692+00:00', '--job-id', '7', '--raw', '--subdir', 'DAGS_FOLDER/mlflow.py', '--cfg-path', '/tmp/tmplo047na_']
[2025-05-12T21:23:55.238+0500] {standard_task_runner.py:85} INFO - Job 7: Subtask track_raw_data
[2025-05-12T21:23:55.872+0500] {task_command.py:416} INFO - Running <TaskInstance: data_pipeline_dag.track_raw_data manual__2025-05-12T16:23:27.408692+00:00 [running]> on host maemoon-Inspiron-15-3567
[2025-05-12T21:23:56.255+0500] {taskinstance.py:1662} INFO - Exporting env vars: AIRFLOW_CTX_DAG_OWNER='airflow' AIRFLOW_CTX_DAG_ID='data_pipeline_dag' AIRFLOW_CTX_TASK_ID='track_raw_data' AIRFLOW_CTX_EXECUTION_DATE='2025-05-12T16:23:27.408692+00:00' AIRFLOW_CTX_TRY_NUMBER='1' AIRFLOW_CTX_DAG_RUN_ID='manual__2025-05-12T16:23:27.408692+00:00'
[2025-05-12T21:23:56.257+0500] {taskinstance.py:1937} ERROR - Task failed with exception
Traceback (most recent call last):
  File "/home/maemoon/Documents/MLOPS_Project/env/lib/python3.10/site-packages/airflow/operators/python.py", line 192, in execute
    return_value = self.execute_callable()
  File "/home/maemoon/Documents/MLOPS_Project/env/lib/python3.10/site-packages/airflow/operators/python.py", line 209, in execute_callable
    return self.python_callable(*self.op_args, **self.op_kwargs)
  File "/home/maemoon/Documents/MLOPS_Project/dags/Tasks/tracking.py", line 6, in track_raw_data
    subprocess.run(['dvc', 'add', 'WeatherData/Lahore_Forecast.csv'])
  File "/usr/lib/python3.10/subprocess.py", line 503, in run
    with Popen(*popenargs, **kwargs) as process:
  File "/usr/lib/python3.10/subprocess.py", line 971, in __init__
    self._execute_child(args, executable, preexec_fn, close_fds,
  File "/usr/lib/python3.10/subprocess.py", line 1863, in _execute_child
    raise child_exception_type(errno_num, err_msg, err_filename)
FileNotFoundError: [Errno 2] No such file or directory: 'dvc'
[2025-05-12T21:23:56.263+0500] {taskinstance.py:1400} INFO - Marking task as FAILED. dag_id=data_pipeline_dag, task_id=track_raw_data, execution_date=20250512T162327, start_date=20250512T162355, end_date=20250512T162356
[2025-05-12T21:23:56.364+0500] {standard_task_runner.py:104} ERROR - Failed to execute job 7 for task track_raw_data ([Errno 2] No such file or directory: 'dvc'; 56044)
[2025-05-12T21:23:56.373+0500] {local_task_job_runner.py:228} INFO - Task exited with return code 1
[2025-05-12T21:23:56.393+0500] {taskinstance.py:2778} INFO - 0 downstream tasks scheduled from follow-on schedule check
