[2025-05-12T23:15:41.953+0500] {taskinstance.py:1159} INFO - Dependencies all met for dep_context=non-requeueable deps ti=<TaskInstance: data_pipeline_dag.track_raw_data manual__2025-05-12T18:15:25.565894+00:00 [queued]>
[2025-05-12T23:15:41.958+0500] {taskinstance.py:1159} INFO - Dependencies all met for dep_context=requeueable deps ti=<TaskInstance: data_pipeline_dag.track_raw_data manual__2025-05-12T18:15:25.565894+00:00 [queued]>
[2025-05-12T23:15:41.958+0500] {taskinstance.py:1361} INFO - Starting attempt 1 of 1
[2025-05-12T23:15:42.080+0500] {taskinstance.py:1382} INFO - Executing <Task(PythonOperator): track_raw_data> on 2025-05-12 18:15:25.565894+00:00
[2025-05-12T23:15:42.085+0500] {standard_task_runner.py:57} INFO - Started process 86724 to run task
[2025-05-12T23:15:42.088+0500] {standard_task_runner.py:84} INFO - Running: ['airflow', 'tasks', 'run', 'data_pipeline_dag', 'track_raw_data', 'manual__2025-05-12T18:15:25.565894+00:00', '--job-id', '45', '--raw', '--subdir', 'DAGS_FOLDER/mlflow.py', '--cfg-path', '/tmp/tmppv2dz5jo']
[2025-05-12T23:15:42.089+0500] {standard_task_runner.py:85} INFO - Job 45: Subtask track_raw_data
[2025-05-12T23:15:42.211+0500] {task_command.py:416} INFO - Running <TaskInstance: data_pipeline_dag.track_raw_data manual__2025-05-12T18:15:25.565894+00:00 [running]> on host maemoon-Inspiron-15-3567
[2025-05-12T23:15:42.429+0500] {taskinstance.py:1662} INFO - Exporting env vars: AIRFLOW_CTX_DAG_OWNER='airflow' AIRFLOW_CTX_DAG_ID='data_pipeline_dag' AIRFLOW_CTX_TASK_ID='track_raw_data' AIRFLOW_CTX_EXECUTION_DATE='2025-05-12T18:15:25.565894+00:00' AIRFLOW_CTX_TRY_NUMBER='1' AIRFLOW_CTX_DAG_RUN_ID='manual__2025-05-12T18:15:25.565894+00:00'
[2025-05-12T23:15:43.718+0500] {logging_mixin.py:151} INFO - Raw data tracked with DVC
[2025-05-12T23:15:43.795+0500] {connectionpool.py:823} WARNING - Retrying (JitteredRetry(total=6, connect=6, read=7, redirect=7, status=7)) after connection broken by 'NewConnectionError('<urllib3.connection.HTTPConnection object at 0x721c78599f90>: Failed to establish a new connection: [Errno 111] Connection refused')': /api/2.0/mlflow/runs/create
[2025-05-12T23:15:47.799+0500] {connectionpool.py:823} WARNING - Retrying (JitteredRetry(total=5, connect=5, read=7, redirect=7, status=7)) after connection broken by 'NewConnectionError('<urllib3.connection.HTTPConnection object at 0x721c7859aa10>: Failed to establish a new connection: [Errno 111] Connection refused')': /api/2.0/mlflow/runs/create
[2025-05-12T23:15:55.809+0500] {connectionpool.py:823} WARNING - Retrying (JitteredRetry(total=4, connect=4, read=7, redirect=7, status=7)) after connection broken by 'NewConnectionError('<urllib3.connection.HTTPConnection object at 0x721c7859b580>: Failed to establish a new connection: [Errno 111] Connection refused')': /api/2.0/mlflow/runs/create
[2025-05-12T23:16:11.826+0500] {connectionpool.py:823} WARNING - Retrying (JitteredRetry(total=3, connect=3, read=7, redirect=7, status=7)) after connection broken by 'NewConnectionError('<urllib3.connection.HTTPConnection object at 0x721c7859b760>: Failed to establish a new connection: [Errno 111] Connection refused')': /api/2.0/mlflow/runs/create
[2025-05-12T23:16:43.838+0500] {connectionpool.py:823} WARNING - Retrying (JitteredRetry(total=2, connect=2, read=7, redirect=7, status=7)) after connection broken by 'NewConnectionError('<urllib3.connection.HTTPConnection object at 0x721c78598cd0>: Failed to establish a new connection: [Errno 111] Connection refused')': /api/2.0/mlflow/runs/create
[2025-05-12T23:17:47.895+0500] {connectionpool.py:823} WARNING - Retrying (JitteredRetry(total=1, connect=1, read=7, redirect=7, status=7)) after connection broken by 'NewConnectionError('<urllib3.connection.HTTPConnection object at 0x721c7859a5f0>: Failed to establish a new connection: [Errno 111] Connection refused')': /api/2.0/mlflow/runs/create
[2025-05-12T23:19:47.997+0500] {connectionpool.py:823} WARNING - Retrying (JitteredRetry(total=0, connect=0, read=7, redirect=7, status=7)) after connection broken by 'NewConnectionError('<urllib3.connection.HTTPConnection object at 0x721c78599f00>: Failed to establish a new connection: [Errno 111] Connection refused')': /api/2.0/mlflow/runs/create
[2025-05-12T23:19:47.998+0500] {taskinstance.py:1937} ERROR - Task failed with exception
Traceback (most recent call last):
  File "/home/maemoon/Documents/MLOPS_Project/env/lib/python3.10/site-packages/urllib3/connection.py", line 174, in _new_conn
    conn = connection.create_connection(
  File "/home/maemoon/Documents/MLOPS_Project/env/lib/python3.10/site-packages/urllib3/util/connection.py", line 95, in create_connection
    raise err
  File "/home/maemoon/Documents/MLOPS_Project/env/lib/python3.10/site-packages/urllib3/util/connection.py", line 85, in create_connection
    sock.connect(sa)
ConnectionRefusedError: [Errno 111] Connection refused

During handling of the above exception, another exception occurred:

Traceback (most recent call last):
  File "/home/maemoon/Documents/MLOPS_Project/env/lib/python3.10/site-packages/urllib3/connectionpool.py", line 714, in urlopen
    httplib_response = self._make_request(
  File "/home/maemoon/Documents/MLOPS_Project/env/lib/python3.10/site-packages/urllib3/connectionpool.py", line 415, in _make_request
    conn.request(method, url, **httplib_request_kw)
  File "/home/maemoon/Documents/MLOPS_Project/env/lib/python3.10/site-packages/urllib3/connection.py", line 244, in request
    super(HTTPConnection, self).request(method, url, body=body, headers=headers)
  File "/usr/lib/python3.10/http/client.py", line 1283, in request
    self._send_request(method, url, body, headers, encode_chunked)
  File "/usr/lib/python3.10/http/client.py", line 1329, in _send_request
    self.endheaders(body, encode_chunked=encode_chunked)
  File "/usr/lib/python3.10/http/client.py", line 1278, in endheaders
    self._send_output(message_body, encode_chunked=encode_chunked)
  File "/usr/lib/python3.10/http/client.py", line 1038, in _send_output
    self.send(msg)
  File "/usr/lib/python3.10/http/client.py", line 976, in send
    self.connect()
  File "/home/maemoon/Documents/MLOPS_Project/env/lib/python3.10/site-packages/urllib3/connection.py", line 205, in connect
    conn = self._new_conn()
  File "/home/maemoon/Documents/MLOPS_Project/env/lib/python3.10/site-packages/urllib3/connection.py", line 186, in _new_conn
    raise NewConnectionError(
urllib3.exceptions.NewConnectionError: <urllib3.connection.HTTPConnection object at 0x721c7859ab30>: Failed to establish a new connection: [Errno 111] Connection refused

During handling of the above exception, another exception occurred:

Traceback (most recent call last):
  File "/home/maemoon/Documents/MLOPS_Project/env/lib/python3.10/site-packages/requests/adapters.py", line 486, in send
    resp = conn.urlopen(
  File "/home/maemoon/Documents/MLOPS_Project/env/lib/python3.10/site-packages/urllib3/connectionpool.py", line 826, in urlopen
    return self.urlopen(
  File "/home/maemoon/Documents/MLOPS_Project/env/lib/python3.10/site-packages/urllib3/connectionpool.py", line 826, in urlopen
    return self.urlopen(
  File "/home/maemoon/Documents/MLOPS_Project/env/lib/python3.10/site-packages/urllib3/connectionpool.py", line 826, in urlopen
    return self.urlopen(
  [Previous line repeated 4 more times]
  File "/home/maemoon/Documents/MLOPS_Project/env/lib/python3.10/site-packages/urllib3/connectionpool.py", line 798, in urlopen
    retries = retries.increment(
  File "/home/maemoon/Documents/MLOPS_Project/env/lib/python3.10/site-packages/urllib3/util/retry.py", line 592, in increment
    raise MaxRetryError(_pool, url, error or ResponseError(cause))
urllib3.exceptions.MaxRetryError: HTTPConnectionPool(host='localhost', port=5000): Max retries exceeded with url: /api/2.0/mlflow/runs/create (Caused by NewConnectionError('<urllib3.connection.HTTPConnection object at 0x721c7859ab30>: Failed to establish a new connection: [Errno 111] Connection refused'))

During handling of the above exception, another exception occurred:

Traceback (most recent call last):
  File "/home/maemoon/Documents/MLOPS_Project/env/lib/python3.10/site-packages/mlflow/utils/rest_utils.py", line 184, in http_request
    return _get_http_response_with_retries(
  File "/home/maemoon/Documents/MLOPS_Project/env/lib/python3.10/site-packages/mlflow/utils/request_utils.py", line 237, in _get_http_response_with_retries
    return session.request(method, url, allow_redirects=allow_redirects, **kwargs)
  File "/home/maemoon/Documents/MLOPS_Project/env/lib/python3.10/site-packages/requests/sessions.py", line 589, in request
    resp = self.send(prep, **send_kwargs)
  File "/home/maemoon/Documents/MLOPS_Project/env/lib/python3.10/site-packages/requests/sessions.py", line 703, in send
    r = adapter.send(request, **kwargs)
  File "/home/maemoon/Documents/MLOPS_Project/env/lib/python3.10/site-packages/requests/adapters.py", line 519, in send
    raise ConnectionError(e, request=request)
requests.exceptions.ConnectionError: HTTPConnectionPool(host='localhost', port=5000): Max retries exceeded with url: /api/2.0/mlflow/runs/create (Caused by NewConnectionError('<urllib3.connection.HTTPConnection object at 0x721c7859ab30>: Failed to establish a new connection: [Errno 111] Connection refused'))

During handling of the above exception, another exception occurred:

Traceback (most recent call last):
  File "/home/maemoon/Documents/MLOPS_Project/env/lib/python3.10/site-packages/airflow/operators/python.py", line 192, in execute
    return_value = self.execute_callable()
  File "/home/maemoon/Documents/MLOPS_Project/env/lib/python3.10/site-packages/airflow/operators/python.py", line 209, in execute_callable
    return self.python_callable(*self.op_args, **self.op_kwargs)
  File "/home/maemoon/Documents/MLOPS_Project/dags/Tasks/tracking.py", line 14, in track_raw_data
    with mlflow.start_run(run_name="data_tracking"):
  File "/home/maemoon/Documents/MLOPS_Project/env/lib/python3.10/site-packages/mlflow/tracking/fluent.py", line 446, in start_run
    active_run_obj = client.create_run(
  File "/home/maemoon/Documents/MLOPS_Project/env/lib/python3.10/site-packages/mlflow/tracking/client.py", line 418, in create_run
    return self._tracking_client.create_run(experiment_id, start_time, tags, run_name)
  File "/home/maemoon/Documents/MLOPS_Project/env/lib/python3.10/site-packages/mlflow/tracking/_tracking_service/client.py", line 170, in create_run
    return self.store.create_run(
  File "/home/maemoon/Documents/MLOPS_Project/env/lib/python3.10/site-packages/mlflow/store/tracking/rest_store.py", line 220, in create_run
    response_proto = self._call_endpoint(CreateRun, req_body)
  File "/home/maemoon/Documents/MLOPS_Project/env/lib/python3.10/site-packages/mlflow/store/tracking/rest_store.py", line 90, in _call_endpoint
    return call_endpoint(self.get_host_creds(), endpoint, method, json_body, response_proto)
  File "/home/maemoon/Documents/MLOPS_Project/env/lib/python3.10/site-packages/mlflow/utils/rest_utils.py", line 400, in call_endpoint
    response = http_request(**call_kwargs)
  File "/home/maemoon/Documents/MLOPS_Project/env/lib/python3.10/site-packages/mlflow/utils/rest_utils.py", line 207, in http_request
    raise MlflowException(f"API request to {url} failed with exception {e}")
mlflow.exceptions.MlflowException: API request to http://localhost:5000/api/2.0/mlflow/runs/create failed with exception HTTPConnectionPool(host='localhost', port=5000): Max retries exceeded with url: /api/2.0/mlflow/runs/create (Caused by NewConnectionError('<urllib3.connection.HTTPConnection object at 0x721c7859ab30>: Failed to establish a new connection: [Errno 111] Connection refused'))
[2025-05-12T23:19:48.005+0500] {taskinstance.py:1400} INFO - Marking task as FAILED. dag_id=data_pipeline_dag, task_id=track_raw_data, execution_date=20250512T181525, start_date=20250512T181541, end_date=20250512T181948
[2025-05-12T23:19:48.133+0500] {standard_task_runner.py:104} ERROR - Failed to execute job 45 for task track_raw_data (API request to http://localhost:5000/api/2.0/mlflow/runs/create failed with exception HTTPConnectionPool(host='localhost', port=5000): Max retries exceeded with url: /api/2.0/mlflow/runs/create (Caused by NewConnectionError('<urllib3.connection.HTTPConnection object at 0x721c7859ab30>: Failed to establish a new connection: [Errno 111] Connection refused')); 86724)
[2025-05-12T23:19:48.153+0500] {local_task_job_runner.py:228} INFO - Task exited with return code 1
[2025-05-12T23:19:48.169+0500] {taskinstance.py:2778} INFO - 0 downstream tasks scheduled from follow-on schedule check
