[2025-05-12T21:30:07.437+0500] {taskinstance.py:1159} INFO - Dependencies all met for dep_context=non-requeueable deps ti=<TaskInstance: data_pipeline_dag.model_training manual__2025-05-12T16:29:39.152880+00:00 [queued]>
[2025-05-12T21:30:07.446+0500] {taskinstance.py:1159} INFO - Dependencies all met for dep_context=requeueable deps ti=<TaskInstance: data_pipeline_dag.model_training manual__2025-05-12T16:29:39.152880+00:00 [queued]>
[2025-05-12T21:30:07.446+0500] {taskinstance.py:1361} INFO - Starting attempt 1 of 1
[2025-05-12T21:30:07.565+0500] {taskinstance.py:1382} INFO - Executing <Task(PythonOperator): model_training> on 2025-05-12 16:29:39.152880+00:00
[2025-05-12T21:30:07.568+0500] {standard_task_runner.py:57} INFO - Started process 57796 to run task
[2025-05-12T21:30:07.573+0500] {standard_task_runner.py:84} INFO - Running: ['airflow', 'tasks', 'run', 'data_pipeline_dag', 'model_training', 'manual__2025-05-12T16:29:39.152880+00:00', '--job-id', '14', '--raw', '--subdir', 'DAGS_FOLDER/mlflow.py', '--cfg-path', '/tmp/tmpxb4vsn0j']
[2025-05-12T21:30:07.574+0500] {standard_task_runner.py:85} INFO - Job 14: Subtask model_training
[2025-05-12T21:30:07.710+0500] {task_command.py:416} INFO - Running <TaskInstance: data_pipeline_dag.model_training manual__2025-05-12T16:29:39.152880+00:00 [running]> on host maemoon-Inspiron-15-3567
[2025-05-12T21:30:07.914+0500] {taskinstance.py:1662} INFO - Exporting env vars: AIRFLOW_CTX_DAG_OWNER='airflow' AIRFLOW_CTX_DAG_ID='data_pipeline_dag' AIRFLOW_CTX_TASK_ID='model_training' AIRFLOW_CTX_EXECUTION_DATE='2025-05-12T16:29:39.152880+00:00' AIRFLOW_CTX_TRY_NUMBER='1' AIRFLOW_CTX_DAG_RUN_ID='manual__2025-05-12T16:29:39.152880+00:00'
[2025-05-12T21:30:09.418+0500] {taskinstance.py:1937} ERROR - Task failed with exception
Traceback (most recent call last):
  File "/home/maemoon/Documents/MLOPS_Project/env/lib/python3.10/site-packages/airflow/operators/python.py", line 192, in execute
    return_value = self.execute_callable()
  File "/home/maemoon/Documents/MLOPS_Project/env/lib/python3.10/site-packages/airflow/operators/python.py", line 209, in execute_callable
    return self.python_callable(*self.op_args, **self.op_kwargs)
  File "/home/maemoon/Documents/MLOPS_Project/dags/Tasks/model_training.py", line 11, in model_training
    df = pd.read_csv('/home/maemoon/Documents/University/MLOPS/Assignments/A3/MLOPSA3/PreprocessedWeatherData/Processed_Lahore_Forecast.csv')
  File "/home/maemoon/Documents/MLOPS_Project/env/lib/python3.10/site-packages/pandas/io/parsers/readers.py", line 1026, in read_csv
    return _read(filepath_or_buffer, kwds)
  File "/home/maemoon/Documents/MLOPS_Project/env/lib/python3.10/site-packages/pandas/io/parsers/readers.py", line 620, in _read
    parser = TextFileReader(filepath_or_buffer, **kwds)
  File "/home/maemoon/Documents/MLOPS_Project/env/lib/python3.10/site-packages/pandas/io/parsers/readers.py", line 1620, in __init__
    self._engine = self._make_engine(f, self.engine)
  File "/home/maemoon/Documents/MLOPS_Project/env/lib/python3.10/site-packages/pandas/io/parsers/readers.py", line 1880, in _make_engine
    self.handles = get_handle(
  File "/home/maemoon/Documents/MLOPS_Project/env/lib/python3.10/site-packages/pandas/io/common.py", line 873, in get_handle
    handle = open(
FileNotFoundError: [Errno 2] No such file or directory: '/home/maemoon/Documents/University/MLOPS/Assignments/A3/MLOPSA3/PreprocessedWeatherData/Processed_Lahore_Forecast.csv'
[2025-05-12T21:30:09.437+0500] {taskinstance.py:1400} INFO - Marking task as FAILED. dag_id=data_pipeline_dag, task_id=model_training, execution_date=20250512T162939, start_date=20250512T163007, end_date=20250512T163009
[2025-05-12T21:30:09.565+0500] {standard_task_runner.py:104} ERROR - Failed to execute job 14 for task model_training ([Errno 2] No such file or directory: '/home/maemoon/Documents/University/MLOPS/Assignments/A3/MLOPSA3/PreprocessedWeatherData/Processed_Lahore_Forecast.csv'; 57796)
[2025-05-12T21:30:09.594+0500] {local_task_job_runner.py:228} INFO - Task exited with return code 1
[2025-05-12T21:30:09.613+0500] {taskinstance.py:2778} INFO - 0 downstream tasks scheduled from follow-on schedule check
