[2025-05-12T23:11:16.189+0500] {taskinstance.py:1159} INFO - Dependencies all met for dep_context=non-requeueable deps ti=<TaskInstance: data_pipeline_dag.track_raw_data manual__2025-05-12T18:10:53.946844+00:00 [queued]>
[2025-05-12T23:11:16.195+0500] {taskinstance.py:1159} INFO - Dependencies all met for dep_context=requeueable deps ti=<TaskInstance: data_pipeline_dag.track_raw_data manual__2025-05-12T18:10:53.946844+00:00 [queued]>
[2025-05-12T23:11:16.195+0500] {taskinstance.py:1361} INFO - Starting attempt 1 of 1
[2025-05-12T23:11:16.315+0500] {taskinstance.py:1382} INFO - Executing <Task(PythonOperator): track_raw_data> on 2025-05-12 18:10:53.946844+00:00
[2025-05-12T23:11:16.321+0500] {standard_task_runner.py:57} INFO - Started process 85324 to run task
[2025-05-12T23:11:16.324+0500] {standard_task_runner.py:84} INFO - Running: ['airflow', 'tasks', 'run', 'data_pipeline_dag', 'track_raw_data', 'manual__2025-05-12T18:10:53.946844+00:00', '--job-id', '41', '--raw', '--subdir', 'DAGS_FOLDER/mlflow.py', '--cfg-path', '/tmp/tmp2y_7c419']
[2025-05-12T23:11:16.325+0500] {standard_task_runner.py:85} INFO - Job 41: Subtask track_raw_data
[2025-05-12T23:11:16.485+0500] {task_command.py:416} INFO - Running <TaskInstance: data_pipeline_dag.track_raw_data manual__2025-05-12T18:10:53.946844+00:00 [running]> on host maemoon-Inspiron-15-3567
[2025-05-12T23:11:16.698+0500] {taskinstance.py:1662} INFO - Exporting env vars: AIRFLOW_CTX_DAG_OWNER='airflow' AIRFLOW_CTX_DAG_ID='data_pipeline_dag' AIRFLOW_CTX_TASK_ID='track_raw_data' AIRFLOW_CTX_EXECUTION_DATE='2025-05-12T18:10:53.946844+00:00' AIRFLOW_CTX_TRY_NUMBER='1' AIRFLOW_CTX_DAG_RUN_ID='manual__2025-05-12T18:10:53.946844+00:00'
[2025-05-12T23:11:22.924+0500] {logging_mixin.py:151} INFO - Raw data tracked with DVC
[2025-05-12T23:11:23.880+0500] {connectionpool.py:823} WARNING - Retrying (JitteredRetry(total=6, connect=6, read=7, redirect=7, status=7)) after connection broken by 'NewConnectionError('<urllib3.connection.HTTPConnection object at 0x7d79b3e61cc0>: Failed to establish a new connection: [Errno 111] Connection refused')': /api/2.0/mlflow/runs/create
[2025-05-12T23:11:27.885+0500] {connectionpool.py:823} WARNING - Retrying (JitteredRetry(total=5, connect=5, read=7, redirect=7, status=7)) after connection broken by 'NewConnectionError('<urllib3.connection.HTTPConnection object at 0x7d79b3e62770>: Failed to establish a new connection: [Errno 111] Connection refused')': /api/2.0/mlflow/runs/create
[2025-05-12T23:11:35.889+0500] {connectionpool.py:823} WARNING - Retrying (JitteredRetry(total=4, connect=4, read=7, redirect=7, status=7)) after connection broken by 'NewConnectionError('<urllib3.connection.HTTPConnection object at 0x7d79b3e632e0>: Failed to establish a new connection: [Errno 111] Connection refused')': /api/2.0/mlflow/runs/create
[2025-05-12T23:11:51.907+0500] {connectionpool.py:823} WARNING - Retrying (JitteredRetry(total=3, connect=3, read=7, redirect=7, status=7)) after connection broken by 'NewConnectionError('<urllib3.connection.HTTPConnection object at 0x7d79b3e63250>: Failed to establish a new connection: [Errno 111] Connection refused')': /api/2.0/mlflow/runs/create
[2025-05-12T23:13:02.228+0500] {connectionpool.py:823} WARNING - Retrying (JitteredRetry(total=2, connect=2, read=7, redirect=7, status=7)) after connection broken by 'NewConnectionError('<urllib3.connection.HTTPConnection object at 0x7d79b3e62f80>: Failed to establish a new connection: [Errno 111] Connection refused')': /api/2.0/mlflow/runs/create
[2025-05-12T23:14:06.285+0500] {connectionpool.py:823} WARNING - Retrying (JitteredRetry(total=1, connect=1, read=7, redirect=7, status=7)) after connection broken by 'NewConnectionError('<urllib3.connection.HTTPConnection object at 0x7d79b3e622f0>: Failed to establish a new connection: [Errno 111] Connection refused')': /api/2.0/mlflow/runs/create
[2025-05-12T23:14:32.529+0500] {process_utils.py:131} INFO - Sending Signals.SIGTERM to group 85324. PIDs of all processes in the group: [85324]
[2025-05-12T23:14:32.529+0500] {process_utils.py:86} INFO - Sending the signal Signals.SIGTERM to group 85324
[2025-05-12T23:14:32.529+0500] {taskinstance.py:1632} ERROR - Received SIGTERM. Terminating subprocesses.
[2025-05-12T23:14:32.530+0500] {taskinstance.py:1937} ERROR - Task failed with exception
Traceback (most recent call last):
  File "/home/maemoon/Documents/MLOPS_Project/env/lib/python3.10/site-packages/urllib3/connection.py", line 174, in _new_conn
    conn = connection.create_connection(
  File "/home/maemoon/Documents/MLOPS_Project/env/lib/python3.10/site-packages/urllib3/util/connection.py", line 95, in create_connection
    raise err
  File "/home/maemoon/Documents/MLOPS_Project/env/lib/python3.10/site-packages/urllib3/util/connection.py", line 85, in create_connection
    sock.connect(sa)
ConnectionRefusedError: [Errno 111] Connection refused

During handling of the above exception, another exception occurred:

Traceback (most recent call last):
  File "/home/maemoon/Documents/MLOPS_Project/env/lib/python3.10/site-packages/urllib3/connectionpool.py", line 714, in urlopen
    httplib_response = self._make_request(
  File "/home/maemoon/Documents/MLOPS_Project/env/lib/python3.10/site-packages/urllib3/connectionpool.py", line 415, in _make_request
    conn.request(method, url, **httplib_request_kw)
  File "/home/maemoon/Documents/MLOPS_Project/env/lib/python3.10/site-packages/urllib3/connection.py", line 244, in request
    super(HTTPConnection, self).request(method, url, body=body, headers=headers)
  File "/usr/lib/python3.10/http/client.py", line 1283, in request
    self._send_request(method, url, body, headers, encode_chunked)
  File "/usr/lib/python3.10/http/client.py", line 1329, in _send_request
    self.endheaders(body, encode_chunked=encode_chunked)
  File "/usr/lib/python3.10/http/client.py", line 1278, in endheaders
    self._send_output(message_body, encode_chunked=encode_chunked)
  File "/usr/lib/python3.10/http/client.py", line 1038, in _send_output
    self.send(msg)
  File "/usr/lib/python3.10/http/client.py", line 976, in send
    self.connect()
  File "/home/maemoon/Documents/MLOPS_Project/env/lib/python3.10/site-packages/urllib3/connection.py", line 205, in connect
    conn = self._new_conn()
  File "/home/maemoon/Documents/MLOPS_Project/env/lib/python3.10/site-packages/urllib3/connection.py", line 186, in _new_conn
    raise NewConnectionError(
urllib3.exceptions.NewConnectionError: <urllib3.connection.HTTPConnection object at 0x7d79b3e62500>: Failed to establish a new connection: [Errno 111] Connection refused

During handling of the above exception, another exception occurred:

Traceback (most recent call last):
  File "/home/maemoon/Documents/MLOPS_Project/env/lib/python3.10/site-packages/mlflow/utils/rest_utils.py", line 184, in http_request
    return _get_http_response_with_retries(
  File "/home/maemoon/Documents/MLOPS_Project/env/lib/python3.10/site-packages/mlflow/utils/request_utils.py", line 237, in _get_http_response_with_retries
    return session.request(method, url, allow_redirects=allow_redirects, **kwargs)
  File "/home/maemoon/Documents/MLOPS_Project/env/lib/python3.10/site-packages/requests/sessions.py", line 589, in request
    resp = self.send(prep, **send_kwargs)
  File "/home/maemoon/Documents/MLOPS_Project/env/lib/python3.10/site-packages/requests/sessions.py", line 703, in send
    r = adapter.send(request, **kwargs)
  File "/home/maemoon/Documents/MLOPS_Project/env/lib/python3.10/site-packages/requests/adapters.py", line 486, in send
    resp = conn.urlopen(
  File "/home/maemoon/Documents/MLOPS_Project/env/lib/python3.10/site-packages/urllib3/connectionpool.py", line 826, in urlopen
    return self.urlopen(
  File "/home/maemoon/Documents/MLOPS_Project/env/lib/python3.10/site-packages/urllib3/connectionpool.py", line 826, in urlopen
    return self.urlopen(
  File "/home/maemoon/Documents/MLOPS_Project/env/lib/python3.10/site-packages/urllib3/connectionpool.py", line 826, in urlopen
    return self.urlopen(
  [Previous line repeated 3 more times]
  File "/home/maemoon/Documents/MLOPS_Project/env/lib/python3.10/site-packages/urllib3/connectionpool.py", line 801, in urlopen
    retries.sleep()
  File "/home/maemoon/Documents/MLOPS_Project/env/lib/python3.10/site-packages/urllib3/util/retry.py", line 432, in sleep
    self._sleep_backoff()
  File "/home/maemoon/Documents/MLOPS_Project/env/lib/python3.10/site-packages/urllib3/util/retry.py", line 416, in _sleep_backoff
    time.sleep(backoff)
  File "/home/maemoon/Documents/MLOPS_Project/env/lib/python3.10/site-packages/airflow/models/taskinstance.py", line 1634, in signal_handler
    raise AirflowException("Task received SIGTERM signal")
airflow.exceptions.AirflowException: Task received SIGTERM signal

During handling of the above exception, another exception occurred:

Traceback (most recent call last):
  File "/home/maemoon/Documents/MLOPS_Project/env/lib/python3.10/site-packages/airflow/operators/python.py", line 192, in execute
    return_value = self.execute_callable()
  File "/home/maemoon/Documents/MLOPS_Project/env/lib/python3.10/site-packages/airflow/operators/python.py", line 209, in execute_callable
    return self.python_callable(*self.op_args, **self.op_kwargs)
  File "/home/maemoon/Documents/MLOPS_Project/dags/Tasks/tracking.py", line 14, in track_raw_data
    with mlflow.start_run(run_name="data_tracking"):
  File "/home/maemoon/Documents/MLOPS_Project/env/lib/python3.10/site-packages/mlflow/tracking/fluent.py", line 446, in start_run
    active_run_obj = client.create_run(
  File "/home/maemoon/Documents/MLOPS_Project/env/lib/python3.10/site-packages/mlflow/tracking/client.py", line 418, in create_run
    return self._tracking_client.create_run(experiment_id, start_time, tags, run_name)
  File "/home/maemoon/Documents/MLOPS_Project/env/lib/python3.10/site-packages/mlflow/tracking/_tracking_service/client.py", line 170, in create_run
    return self.store.create_run(
  File "/home/maemoon/Documents/MLOPS_Project/env/lib/python3.10/site-packages/mlflow/store/tracking/rest_store.py", line 220, in create_run
    response_proto = self._call_endpoint(CreateRun, req_body)
  File "/home/maemoon/Documents/MLOPS_Project/env/lib/python3.10/site-packages/mlflow/store/tracking/rest_store.py", line 90, in _call_endpoint
    return call_endpoint(self.get_host_creds(), endpoint, method, json_body, response_proto)
  File "/home/maemoon/Documents/MLOPS_Project/env/lib/python3.10/site-packages/mlflow/utils/rest_utils.py", line 400, in call_endpoint
    response = http_request(**call_kwargs)
  File "/home/maemoon/Documents/MLOPS_Project/env/lib/python3.10/site-packages/mlflow/utils/rest_utils.py", line 207, in http_request
    raise MlflowException(f"API request to {url} failed with exception {e}")
mlflow.exceptions.MlflowException: API request to http://localhost:5000/api/2.0/mlflow/runs/create failed with exception Task received SIGTERM signal
[2025-05-12T23:14:32.659+0500] {taskinstance.py:1400} INFO - Marking task as FAILED. dag_id=data_pipeline_dag, task_id=track_raw_data, execution_date=20250512T181053, start_date=20250512T181116, end_date=20250512T181432
[2025-05-12T23:14:32.781+0500] {standard_task_runner.py:104} ERROR - Failed to execute job 41 for task track_raw_data (API request to http://localhost:5000/api/2.0/mlflow/runs/create failed with exception Task received SIGTERM signal; 85324)
[2025-05-12T23:14:32.822+0500] {process_utils.py:79} INFO - Process psutil.Process(pid=85324, status='terminated', exitcode=1, started='23:11:16') (85324) terminated with exit code 1
